<?xml version="1.0"?>
<robot xmlns:xacro="http://ros.org/wiki/xacro">

    <xacro:include filename="$(find robot_description)/robot/inertial_macros.xacro"/>


    <xacro:include filename="$(find robot_description)/urdf/wheel/wheel.transmission.xacro"/>
    <xacro:include filename="$(find robot_description)/urdf/wheel/wheel.gazebo.xacro"/>

    <material name="grey">
        <color rgba="0.5 0.5 0.5 1"/>
    </material>

    <xacro:property name="wheel_mass" value="0.25"/>
    <xacro:property name="wheel_radius" value="0.048"/>
    <xacro:property name="wheel_width" value="0.01"/>

    <xacro:macro name="wheel_v0" params="prefix parent *joint_origin *joint_axis">
        <joint name="${prefix}_wheel_joint" type="continuous">
            <xacro:insert_block name="joint_origin"/>
            <parent link="${parent}"/>
            <child link="${prefix}_wheel_link"/>
            <limit effort="100" velocity="100"/>
            <xacro:insert_block name="joint_axis"/>
        </joint>

        <link name="${prefix}_wheel_link">
            <visual>
                <origin xyz="0 0 0" rpy="0 0 0"/>
                <geometry>
                    <mesh filename="package://robot_description/meshes/STL/wheel_base/wheel_base.stl"/>
                </geometry>
                <material name="grey"/>
            </visual>
            <collision>
                <origin xyz="0 0 0" rpy="0 0 0"/>
                <geometry>
                    <mesh filename="package://robot_description/meshes/STL/wheel_base/wheel_base.stl"/>
                </geometry>
            </collision>
            <xacro:inertial_cylinder mass="${wheel_mass}" length="${wheel_width}" radius="${wheel_radius}">-->
                        <origin xyz="0 0 0" rpy="0 0 0"/>
            </xacro:inertial_cylinder>

            <surface>
                <friction>
                    <ode>
                        <mu1>1.2</mu1>
                        <mu2>1.2</mu2>
                        <kp>1e15</kp>
                        <kd>1e13</kd>
                    </ode>
                </friction>
                <bounce>
                    <restitution_coefficient>0.01</restitution_coefficient>
                    <threshold>0</threshold>
                </bounce>
                <contact>
                    <ode>
                        <max_vel>10</max_vel>
                    </ode>
                </contact>
            </surface>
        </link>
    </xacro:macro>

</robot>
